<mujoco model="mars_rover_scene">
  <compiler angle="degree" coordinate="local" inertiafromgeom="true"/>

  <option timestep="0.002" gravity="0 0 -3.721">
    <flag energy="enable"/>
  </option>

  <default>
    <geom solref="0.01 1" solimp="0.95 0.99 0.001" friction="1.2 0.05 0.02"/>
  </default>

  <asset>
    <texture name="sky" type="skybox" builtin="gradient" rgb1="0.03 0.02 0.05" rgb2="0.65 0.32 0.18" width="512" height="512"/>
    <texture name="soil_tex" type="2d" builtin="gradient" rgb1="0.72 0.35 0.22" rgb2="0.42 0.18 0.09" width="2048" height="2048"/>
    <material name="terrain_mat" texture="soil_tex" texrepeat="8 8" shininess="0.03" specular="0.03"/>
    <material name="ingenuity_body_mat" rgba="0.92 0.92 0.86 1"/>
    <material name="ingenuity_blades_mat" rgba="0.08 0.08 0.08 1"/>
    <material name="ingenuity_legs_mat" rgba="0.02 0.02 0.02 1"/>
    <material name="rover_chassis_mat" rgba="0.88 0.66 0.18 1" shininess="0.35" specular="0.2"/>
    <material name="rover_panel_mat" rgba="0.05 0.12 0.25 1" shininess="0.5" specular="0.35"/>
    <material name="rover_wheel_mat" rgba="0.08 0.08 0.08 1"/>
    <material name="arm_mat" rgba="0.62 0.68 0.72 1" shininess="0.25" specular="0.15"/>
    <material name="arm_joint_mat" rgba="0.12 0.16 0.18 1" shininess="0.25" specular="0.15"/>
    <material name="gripper_mat" rgba="0.08 0.08 0.08 1"/>
    <material name="cube_mat" rgba="0.86 0.08 0.24 1" shininess="0.2" specular="0.1"/>
    <material name="target_mat" rgba="0.15 0.8 0.25 0.45" shininess="0.1" specular="0.05"/>

    <mesh name="mars_terrain" file="Mars - Spirit Landing Site_smooth.stl" scale="0.25 0.25 0.25"/>
    <hfield name="mars_heightfield" file="Mars - Spirit Landing Site_heightfield.png" size="21.219839 20.501948 2.819581 0.05"/>
  </asset>

  <worldbody>
    <light directional="true" diffuse="0.85 0.75 0.65" specular="0.2 0.2 0.2" pos="0 0 150" dir="0.3 0.2 -1" castshadow="true"/>
    <light directional="true" diffuse="0.25 0.15 0.1" pos="0 0 100" dir="-0.3 -0.2 -1"/>

    <geom name="terrain_visual" type="mesh" mesh="mars_terrain" material="terrain_mat" contype="0" conaffinity="0" group="2"/>
    <geom name="terrain_collision" type="hfield" hfield="mars_heightfield" pos="4.536614 -5.097652 3.032014" rgba="0 0 0 0" contype="0" conaffinity="0" group="2"/>
    <geom name="rover_drive_plane" type="plane" pos="0 0 3.31" size="8 8 0.1" material="terrain_mat" condim="6" group="1" contype="1" conaffinity="2"/>
    <!-- Dome footprint marker: a translucent disc at the habitat's center. -->
    <geom name="target_pad" type="cylinder" pos="1.64 -0.11 3.312" size="0.30 0.004" material="target_mat" contype="0" conaffinity="0"/>
    <site name="target_site" pos="1.64 -0.11 3.39" size="0.02" rgba="0.1 1 0.2 1"/>

    <!-- 20-cube pile (4 cols x 5 rows, spacing 0.12, centered at (1.65, -0.70)). -->
    <body name="pick_cube_0" pos="1.47 -0.94 3.39"><freejoint name="pick_cube_0_free"/><geom name="pick_cube_0_geom" type="box" size="0.055 0.055 0.055" material="cube_mat" mass="0.08" condim="6" friction="1.2 0.05 0.02" contype="2" conaffinity="4"/></body>
    <body name="pick_cube_1" pos="1.47 -0.82 3.39"><freejoint name="pick_cube_1_free"/><geom name="pick_cube_1_geom" type="box" size="0.055 0.055 0.055" material="cube_mat" mass="0.08" condim="6" friction="1.2 0.05 0.02" contype="2" conaffinity="4"/></body>
    <body name="pick_cube_2" pos="1.47 -0.70 3.39"><freejoint name="pick_cube_2_free"/><geom name="pick_cube_2_geom" type="box" size="0.055 0.055 0.055" material="cube_mat" mass="0.08" condim="6" friction="1.2 0.05 0.02" contype="2" conaffinity="4"/></body>
    <body name="pick_cube_3" pos="1.47 -0.58 3.39"><freejoint name="pick_cube_3_free"/><geom name="pick_cube_3_geom" type="box" size="0.055 0.055 0.055" material="cube_mat" mass="0.08" condim="6" friction="1.2 0.05 0.02" contype="2" conaffinity="4"/></body>
    <body name="pick_cube_4" pos="1.47 -0.46 3.39"><freejoint name="pick_cube_4_free"/><geom name="pick_cube_4_geom" type="box" size="0.055 0.055 0.055" material="cube_mat" mass="0.08" condim="6" friction="1.2 0.05 0.02" contype="2" conaffinity="4"/></body>
    <body name="pick_cube_5" pos="1.59 -0.94 3.39"><freejoint name="pick_cube_5_free"/><geom name="pick_cube_5_geom" type="box" size="0.055 0.055 0.055" material="cube_mat" mass="0.08" condim="6" friction="1.2 0.05 0.02" contype="2" conaffinity="4"/></body>
    <body name="pick_cube_6" pos="1.59 -0.82 3.39"><freejoint name="pick_cube_6_free"/><geom name="pick_cube_6_geom" type="box" size="0.055 0.055 0.055" material="cube_mat" mass="0.08" condim="6" friction="1.2 0.05 0.02" contype="2" conaffinity="4"/></body>
    <body name="pick_cube_7" pos="1.59 -0.70 3.39"><freejoint name="pick_cube_7_free"/><geom name="pick_cube_7_geom" type="box" size="0.055 0.055 0.055" material="cube_mat" mass="0.08" condim="6" friction="1.2 0.05 0.02" contype="2" conaffinity="4"/></body>
    <body name="pick_cube_8" pos="1.59 -0.58 3.39"><freejoint name="pick_cube_8_free"/><geom name="pick_cube_8_geom" type="box" size="0.055 0.055 0.055" material="cube_mat" mass="0.08" condim="6" friction="1.2 0.05 0.02" contype="2" conaffinity="4"/></body>
    <body name="pick_cube_9" pos="1.59 -0.46 3.39"><freejoint name="pick_cube_9_free"/><geom name="pick_cube_9_geom" type="box" size="0.055 0.055 0.055" material="cube_mat" mass="0.08" condim="6" friction="1.2 0.05 0.02" contype="2" conaffinity="4"/></body>
    <body name="pick_cube_10" pos="1.71 -0.94 3.39"><freejoint name="pick_cube_10_free"/><geom name="pick_cube_10_geom" type="box" size="0.055 0.055 0.055" material="cube_mat" mass="0.08" condim="6" friction="1.2 0.05 0.02" contype="2" conaffinity="4"/></body>
    <body name="pick_cube_11" pos="1.71 -0.82 3.39"><freejoint name="pick_cube_11_free"/><geom name="pick_cube_11_geom" type="box" size="0.055 0.055 0.055" material="cube_mat" mass="0.08" condim="6" friction="1.2 0.05 0.02" contype="2" conaffinity="4"/></body>
    <body name="pick_cube_12" pos="1.71 -0.70 3.39"><freejoint name="pick_cube_12_free"/><geom name="pick_cube_12_geom" type="box" size="0.055 0.055 0.055" material="cube_mat" mass="0.08" condim="6" friction="1.2 0.05 0.02" contype="2" conaffinity="4"/></body>
    <body name="pick_cube_13" pos="1.71 -0.58 3.39"><freejoint name="pick_cube_13_free"/><geom name="pick_cube_13_geom" type="box" size="0.055 0.055 0.055" material="cube_mat" mass="0.08" condim="6" friction="1.2 0.05 0.02" contype="2" conaffinity="4"/></body>
    <body name="pick_cube_14" pos="1.71 -0.46 3.39"><freejoint name="pick_cube_14_free"/><geom name="pick_cube_14_geom" type="box" size="0.055 0.055 0.055" material="cube_mat" mass="0.08" condim="6" friction="1.2 0.05 0.02" contype="2" conaffinity="4"/></body>
    <body name="pick_cube_15" pos="1.83 -0.94 3.39"><freejoint name="pick_cube_15_free"/><geom name="pick_cube_15_geom" type="box" size="0.055 0.055 0.055" material="cube_mat" mass="0.08" condim="6" friction="1.2 0.05 0.02" contype="2" conaffinity="4"/></body>
    <body name="pick_cube_16" pos="1.83 -0.82 3.39"><freejoint name="pick_cube_16_free"/><geom name="pick_cube_16_geom" type="box" size="0.055 0.055 0.055" material="cube_mat" mass="0.08" condim="6" friction="1.2 0.05 0.02" contype="2" conaffinity="4"/></body>
    <body name="pick_cube_17" pos="1.83 -0.70 3.39"><freejoint name="pick_cube_17_free"/><geom name="pick_cube_17_geom" type="box" size="0.055 0.055 0.055" material="cube_mat" mass="0.08" condim="6" friction="1.2 0.05 0.02" contype="2" conaffinity="4"/></body>
    <body name="pick_cube_18" pos="1.83 -0.58 3.39"><freejoint name="pick_cube_18_free"/><geom name="pick_cube_18_geom" type="box" size="0.055 0.055 0.055" material="cube_mat" mass="0.08" condim="6" friction="1.2 0.05 0.02" contype="2" conaffinity="4"/></body>
    <body name="pick_cube_19" pos="1.83 -0.46 3.39"><freejoint name="pick_cube_19_free"/><geom name="pick_cube_19_geom" type="box" size="0.055 0.055 0.055" material="cube_mat" mass="0.08" condim="6" friction="1.2 0.05 0.02" contype="2" conaffinity="4"/></body>

    <!-- Stationary rover serving as the mounting platform for the pick/place arm. -->
    <body name="simple_rover" pos="1.25 -0.5 3.55">
      <geom name="rover_chassis" type="box" size="0.36 0.24 0.09" pos="0 0 0" material="rover_chassis_mat" mass="4.0" contype="0" conaffinity="0"/>
      <geom name="rover_solar_panel" type="box" size="0.14 0.22 0.01" pos="-0.22 0 0.105" material="rover_panel_mat" mass="0.2" contype="0" conaffinity="0"/>

      <body name="wheel_fl" pos="0.24 0.31 -0.1">
        <joint name="wheel_fl_joint" type="hinge" axis="0 1 0" damping="0.02"/>
        <geom name="wheel_fl_geom" type="cylinder" size="0.13 0.055" zaxis="0 1 0" material="rover_wheel_mat" mass="0.35" contype="0" conaffinity="0"/>
      </body>
      <body name="wheel_fr" pos="0.24 -0.31 -0.1">
        <joint name="wheel_fr_joint" type="hinge" axis="0 1 0" damping="0.02"/>
        <geom name="wheel_fr_geom" type="cylinder" size="0.13 0.055" zaxis="0 1 0" material="rover_wheel_mat" mass="0.35" contype="0" conaffinity="0"/>
      </body>
      <body name="wheel_rl" pos="-0.24 0.31 -0.1">
        <joint name="wheel_rl_joint" type="hinge" axis="0 1 0" damping="0.02"/>
        <geom name="wheel_rl_geom" type="cylinder" size="0.13 0.055" zaxis="0 1 0" material="rover_wheel_mat" mass="0.35" contype="0" conaffinity="0"/>
      </body>
      <body name="wheel_rr" pos="-0.24 -0.31 -0.1">
        <joint name="wheel_rr_joint" type="hinge" axis="0 1 0" damping="0.02"/>
        <geom name="wheel_rr_geom" type="cylinder" size="0.13 0.055" zaxis="0 1 0" material="rover_wheel_mat" mass="0.35" contype="0" conaffinity="0"/>
      </body>

      <!-- Pick/place arm mounted on top of the rover chassis. -->
      <body name="pick_place_arm" pos="0 0 0.09">
        <geom name="arm_base" type="cylinder" size="0.08 0.045" pos="0 0 0.045" material="arm_joint_mat" mass="5.0" contype="0" conaffinity="0"/>
        <body name="arm_yaw_body" pos="0 0 0.09">
          <joint name="arm_yaw" type="hinge" axis="0 0 1" range="-100 100" damping="1.2"/>
          <geom name="arm_yaw_hub" type="sphere" size="0.075" material="arm_joint_mat" mass="0.4" contype="0" conaffinity="0"/>
          <body name="arm_upper" pos="0 0 0">
            <joint name="arm_shoulder" type="hinge" axis="0 1 0" range="-65 80" damping="1.2"/>
            <geom name="arm_upper_link" type="capsule" fromto="0 0 0 0.42 0 0" size="0.035" material="arm_mat" mass="0.5" contype="0" conaffinity="0"/>
            <body name="arm_forearm" pos="0.42 0 0">
              <joint name="arm_elbow" type="hinge" axis="0 1 0" range="-110 170" damping="1.0"/>
              <geom name="arm_elbow_hub" type="sphere" size="0.055" material="arm_joint_mat" mass="0.25" contype="0" conaffinity="0"/>
              <geom name="arm_forearm_link" type="capsule" fromto="0 0 0 0.34 0 0" size="0.03" material="arm_mat" mass="0.35" contype="0" conaffinity="0"/>
              <body name="arm_wrist_body" pos="0.34 0 0">
                <joint name="arm_wrist" type="hinge" axis="0 1 0" range="-160 160" damping="0.8"/>
                <geom name="arm_wrist_hub" type="sphere" size="0.045" material="arm_joint_mat" mass="0.15" contype="0" conaffinity="0"/>
                <geom name="gripper_palm" type="box" size="0.045 0.09 0.025" pos="0.055 0 0" material="gripper_mat" mass="0.15" contype="0" conaffinity="0"/>
                <site name="ee_site" pos="0.12 0 0" size="0.025" rgba="1 0.2 0.1 1"/>
                <body name="left_finger" pos="0.085 0.055 -0.035">
                  <joint name="left_gripper_slide" type="slide" axis="0 1 0" range="-0.035 0" damping="0.3"/>
                  <geom name="left_finger_geom" type="box" size="0.035 0.012 0.06" material="gripper_mat" mass="0.05" contype="0" conaffinity="0"/>
                </body>
                <body name="right_finger" pos="0.085 -0.055 -0.035">
                  <joint name="right_gripper_slide" type="slide" axis="0 1 0" range="0 0.035" damping="0.3"/>
                  <geom name="right_finger_geom" type="box" size="0.035 0.012 0.06" material="gripper_mat" mass="0.05" contype="0" conaffinity="0"/>
                </body>
              </body>
            </body>
          </body>
        </body>
      </body>
    </body>

    <!-- Lightweight primitive Ingenuity stand-in kept as scenery. -->
    <body name="ingenuity_display" pos="-1 0.75 3.85" euler="0 0 -35">
      <geom name="ingenuity_body" type="box" size="0.11 0.08 0.07" pos="0 0 0" material="ingenuity_body_mat" contype="0" conaffinity="0"/>
      <geom name="ingenuity_mast" type="cylinder" size="0.012 0.32" pos="0 0 0.32" material="ingenuity_legs_mat" contype="0" conaffinity="0"/>
      <geom name="ingenuity_top_blade_a" type="box" size="0.55 0.025 0.006" pos="0 0 0.66" material="ingenuity_blades_mat" contype="0" conaffinity="0"/>
      <geom name="ingenuity_top_blade_b" type="box" size="0.025 0.55 0.006" pos="0 0 0.62" material="ingenuity_blades_mat" contype="0" conaffinity="0"/>
      <geom name="ingenuity_leg_1" type="capsule" fromto="0.08 0.06 -0.03 0.35 0.28 -0.34" size="0.012" material="ingenuity_legs_mat" contype="0" conaffinity="0"/>
      <geom name="ingenuity_leg_2" type="capsule" fromto="-0.08 0.06 -0.03 -0.35 0.28 -0.34" size="0.012" material="ingenuity_legs_mat" contype="0" conaffinity="0"/>
      <geom name="ingenuity_leg_3" type="capsule" fromto="0.08 -0.06 -0.03 0.35 -0.28 -0.34" size="0.012" material="ingenuity_legs_mat" contype="0" conaffinity="0"/>
      <geom name="ingenuity_leg_4" type="capsule" fromto="-0.08 -0.06 -0.03 -0.35 -0.28 -0.34" size="0.012" material="ingenuity_legs_mat" contype="0" conaffinity="0"/>
    </body>
  </worldbody>

  <actuator>
    <motor name="wheel_fl_motor" joint="wheel_fl_joint" gear="1" ctrlrange="-1.2 1.2" ctrllimited="true"/>
    <motor name="wheel_fr_motor" joint="wheel_fr_joint" gear="1" ctrlrange="-1.2 1.2" ctrllimited="true"/>
    <motor name="wheel_rl_motor" joint="wheel_rl_joint" gear="1" ctrlrange="-1.2 1.2" ctrllimited="true"/>
    <motor name="wheel_rr_motor" joint="wheel_rr_joint" gear="1" ctrlrange="-1.2 1.2" ctrllimited="true"/>
    <position name="arm_yaw_pos" joint="arm_yaw" kp="35" ctrlrange="-1.745 1.745" ctrllimited="true"/>
    <position name="arm_shoulder_pos" joint="arm_shoulder" kp="45" ctrlrange="-1.134 1.396" ctrllimited="true"/>
    <position name="arm_elbow_pos" joint="arm_elbow" kp="40" ctrlrange="-1.92 2.967" ctrllimited="true"/>
    <position name="arm_wrist_pos" joint="arm_wrist" kp="25" ctrlrange="-2.793 2.793" ctrllimited="true"/>
    <position name="left_gripper_pos" joint="left_gripper_slide" kp="60" ctrlrange="-0.035 0" ctrllimited="true"/>
    <position name="right_gripper_pos" joint="right_gripper_slide" kp="60" ctrlrange="0 0.035" ctrllimited="true"/>
  </actuator>
</mujoco>
